Workbook

Sheet Material Summary
C4: Available for use | H4: Dimensional Depot
C5: Item | D5: Amount | E5: Source | H5: Item | I5: Amount | J5: Source
C6: Alclad Aluminum Sheet | D6: ='Riveteers District'!K13 -> 26.333333 | E6: Riveteers District | H6: Plastic | I6: 15 | J6: Chandra's Flameworks
C7: Copper Ingots | D7: 99.690889 | E7: Xantcha's Crucible | H7: Fabric | I7: 5 | J7: Chandra's Flameworks
C8: Iron Ingots | D8: ='Darksteel Forge'!L15 -> 130.06126 | E8: Darksteel Forge | H8: Heavy Modular Frame | I8: 1.4065 | J8: Neko's Nexus
C9: Plastic | D9: 58.333 | E9: Chandra's Flameworks | H9: Modular Frames | I9: 2.25 | J9: Neko's Nexus
C10: Plastic | D10: ='Kaladesh Refinery'!K14 -> 30.833333 | E10: Kaladesh Refinery | H10: Motors | I10: 2.5 | J10: Neko's Nexus
C11: Plastic | D11: 29.17 | E11: Jund Pyroclast | H11: Steel Beam | I11: 45 | J11: Neko's Nexus
C12: Plastic | D12: ='Keldon Armory'!L29 -> 115.62947 | E12: Keldon Armory | H12: Rotors | I12: 5 | J12: Neko's Nexus
C13: Quartz Crystals | D13: ='Ketria Crystals'!K14 -> 206.3723 | E13: Ketria Crystals | H13: Encased Industrial Beams | I13: 7.3125 | J13: Neko's Nexus
C14: Silica | D14: ='Riveteers District'!$K$18 -> 89.898889 | E14: Riveteers District | H14: Stators | I14: 3 | J14: Neko's Nexus
C15: Silica | D15: 29.405555 | E15: Ketria Crystals | H15: Quickwire | I15: 30 | J15: Neko's Nexus
C16: Steel Ingots | D16: ='Thran Foundry'!$K$13 -> 112.29452 | E16: Thran Foundry | H16: Portable Miners | I16: 0.5 | J16: Neko's Nexus
C17: Aluminum Ingots | D17: ='Urabrask''s Refinery'!$J$12 -> 57.411111 | E17: Urabrask's Refinery | H17: Steel Pipes | I17: 33.125 | J17: Neko's Nexus
C18: Silica | D18: ='Tollarian Meltdown'!L20 -> 688.2 | E18: Tollarian Meltdown | H18: Concrete | I18: 61.6875 | J18: Neko's Nexus
C19: Dark Matter Crystal | D19: 2.25 | E19: Ydris’ Nexus | H19: Reinforced Iron Plate | I19: 7.25 | J19: Neko's Nexus
C20: Quartz Crystals | D20: ='Aetherflux Reactor'!$K$16 -> 256.18667 | E20: Aetherflux Reactor | H20: Cable | I20: 30 | J20: Neko's Nexus
C21: Silica | D21: ='Aetherflux Reactor'!$K$17 -> 537.224 | E21: Aetherflux Reactor | H21: Wire | I21: 45 | J21: Neko's Nexus
C22: Steel Ingots | D22: ='Aetherflux Reactor'!K22 -> 435.88593 | E22: Aetherflux Reactor | H22: Copper Sheet | I22: 22.5 | J22: Neko's Nexus
C23: Aluminum Ingots | D23: ='Aetherflux Reactor'!$K$24 -> 32.927778 | E23: Aetherflux Reactor | H23: Iron Plate | I23: 20.5 | J23: Neko's Nexus
C24: Nitrogen Gas | D24: ='Aetherflux Reactor'!$K$31 -> 1344.7667 | E24: Aetherflux Reactor | H24: Iron Rods | I24: 15 | J24: Neko's Nexus
C25: Limestone | D25: 194 | E25: Aetherflux Reactor | H25: Screws | I25: 25 | J25: Neko's Nexus
C26: Rubber | D26: ='The Fourfold Furnace'!$K$15 -> 19.812157 | E26: The Fourfold Furnace | H26: Quartz Crystals | I26: 26.25 | J26: Ketria Crystals
C27: Reanimated Sam | D27: ='The Fourfold Furnace'!K18 -> 778.18056 | E27: The Fourfold Furnace | H27: Silica | I27: 19.444 | J27: Ketria Crystals
H28: Crystal Oscilators | I28: 1.5 | J28: Ghirapur Gridworks
H29: High-Speed Connectors | I29: 1.5 | J29: Ghirapur Gridworks
H30: AI Limiters | I30: 2.25 | J30: Ghirapur Gridworks
H31: Computers | I31: 3 | J31: Ghirapur Gridworks
H32: Circuit Boards | I32: 6 | J32: Ghirapur Gridworks
H33: Rubber | I33: 25 | J33: Kaladesh Refinery
H34: Empty Canisters | I34: 20 | J34: Kaladesh Refinery
H35: Modular Engines | I35: 0.5 | J35: The Abyssal Chains of Shandalar
H36: Adaptive Control Units | I36: 0.5 | J36: The Abyssal Chains of Shandalar
H37: Alclcad Aluminum Sheet | I37: 49.333 | J37: Riveteers District
H38: Aluminum Scrap | I38: 12 | J38: Riveteers District
H39: Aluminum Ingots | I39: 45 | J39: Riveteers District
H40: Aluminum Casing | I40: ='Riveteers District'!K16 -> 20.1375 | J40: Riveteers District
H41: Supercomputers | I41: ='Phyrexian Datavault'!J12 -> 0.5 | J41: Phyrexian Datavault
H42: Radio Control Units | I42: 1 | J42: Phyrexian Datavault
H43: Empty Fluid Tank | I43: 5 | J43: Riveteers District
...

Sheet Chandra Flameworks
C4: Name | D4: Chandra's Flameworks | F4: Inputs | K4: Outputs
C5: Parents | D5: None | F5: Item | G5: Amount | H5: Source | K5: Item | L5: Amount | M5: Destination
C6: Children | D6: None | F6: Coal | G6: 480 | H6: Miner | K6: Plastic | L6: 15 | M6: Dimensional Depot
C7: Power Production | D7: 20000 Mw | F7: Sulfur | G7: 480 | H7: Miner | K7: Fabric | L7: 5 | M7: Dimensional Depot
C8: Power Consumption | D8: 3672.6 MW | F8: Water | G8: 780 | H8: Water Extractor | K8: Plastic | L8: 58.333 | M8: Available
C9: Net Gain | D9: 16327.4 MW | F9: Oil | G9: 300 | H9: Oil Extractor | K9: Heavy Oil Residue | L9: 10 | M9: Dimensional Depot

Sheet Darksteel Forge
C4: Name | D4: Darksteel Forge
C5: Parents | D5: None
C6: Children | D6: Thran Foundy, Neko's Nexus, Ghirapur Gridworks, The Abyssal Chains of Shandalar, Keldon Armory, Karn's Conduit, Jund Pyroclast, Tollarian Meltdown, The Mirrodin Trigon, Simic Subline
C7: Power Production | D7: 0 Mw
C8: Power Consumption | D8: 2268.3 MW
C9: Net Gain | D9: -2268.3 MW
C10: Storage | D10: 4600 MW
C11: Cut-Time | D11: 2.02 Hours
F13: Inputs | K13: Outputs
F14: Item | G14: Amount | H14: Source | K14: Item | L14: Amount | M14: Destination | N14: Belt | P14: Middle belt (Middle row and column) going to Neko's Nexus / Ghirapur Gridworks has an extra 331.25
F15: Iron Ore | G15: 1800 | H15: Miner | K15: Iron Ingot | L15: =3342+6/7-L16-L17-L18-L19-L20-L21-L22-L23-L24-L25-L26 -> 130.06126 | M15: Available
F16: Water | G16: 514.272 | H16: Water Extractor | K16: Iron Ingot | L16: 960 | M16: Thran Foundry | N16: Row 3 Column 1 and 2
K17: Iron Ingot | L17: 111.25 | M17: Neko's Nexus | N17: Row 2 Column 2
K18: Iron Ingot | L18: 37.5 | M18: Ghirapur Gridworks | N18: Row 2 Column 2
K19: Iron Ingot | L19: 234.25 | M19: The Abyssal Chains of Shandalar | N19: Row 2 Column 1
K20: Iron Ingot | L20: 150 | M20: Keldon Armory | P20: On the desert
K21: Iron Ingot | L21: 12.013 | M21: Karn's Conduit
K22: Iron Ingot | L22: =9+3/8 -> 9.375 | M22: Jund Pyroclast | P22: Top belt going to has an extra 780 Iron Ingots
K23: Iron Ingot | L23: =628+1243/3645 -> 628.34102 | M23: Tollarian Meltdown
K24: Iron Ingot | L24: =41+47/54 -> 41.87037 | M24: The Mirrodin Trigon
K25: Iron Ingot | L25: =30+230/243 -> 30.946502 | M25: Simic Subline | N25: Bottom Belt
K26: Iron Ingot | L26: 997.25 | M26: Ydris’ Nexus | P26: Middle belt going to Tollarian Meltdown has an extra 151.659 Iron Ingots
P30: Bottom belt going to Keldon Armory, Simic Subline, Karn's Conduit, The Mirrodin Trigon And Jund PYroclast has an extra 195.6402 Iron Ingots
P34: Rest belt going to Ydris Nexus has an extra 130.0612553

Sheet Oran-Rief Mines
B2: Name | C2: Oran-Rief Mines
B3: Parents | C3: None
B4: Children | C4: Neko's Nexus, Ghirapur Gridworks, Phyrexian Datavault, Keldon Armory , Obelisks of Alara, Karn's Conduit, Jund Pyroclast, Simic Subline
B5: Power Production | C5: 0 Mw
B6: Power Consumption | C6: 1011.1 MW
B7: Net Gain | C7: -1011.1 MW
B8: Storage | C8: 2200 MWh
B9: Cut-Time | C9: 2.17 Hours
E11: Inputs | J11: Outputs
E12: Item | F12: Amount | G12: Source | J12: Item | K12: Amount | L12: Destination
E13: Caterium Ore | F13: 576 | G13: Miner | J13: Caterium Ingots | K13: =288-K14-K15-K16-K17-K18-K19-K20-K21 -> 1.2333333 | L13: Dimensional Depot
E14: Water | F14: 576 | G14: Water Extractor | J14: Caterium Ingots | K14: 18 | L14: Neko's Nexus
J15: Caterium Ingots | K15: 18 | L15: Ghirapur Gridworks
J16: Caterium Ingots | K16: =158+1/3 -> 158.33333 | L16: Phyrexian Datavault
J17: Caterium Ingots | K17: 9.6 | L17: Keldon Armory
J18: Caterium Ingots | K18: 72 | L18: Obelisks of Alara
J19: Caterium Ingots | K19: 5 | L19: Karn's Conduit
J20: Caterium Ingots | K20: 2.5 | L20: Jund Pytoclast
J21: Caterium Ingots | K21: =3+1/3 -> 3.3333333 | L21: Simic Subline

Sheet Xantcha's Crucible
B2: Name | C2: Xantcha's Crucible
B3: Parents | C3: None
B4: Children | C4: Neko's Nexus, Ghirapur Gridworks, Phyrexian Datavault, Riveteers District, The Abyssal Chains of Shandalar, Keldon Armory, Tollarian Meltdown
B5: Power Production | C5: 0 Mw
B6: Power Consumption | C6: 2286 MW
B7: Net Gain | C7: -2286 MW
B8: Storage | C8: 8800 MWh
B9: Cut-Time | C9: 3.84 Hours
E11: Inputs | J11: Outputs
E12: Item | F12: Amount | G12: Source | J12: Item | K12: Amount | L12: Destination | M12: Belt | O12: Top right uncompressed belt going to Neko's Nexus and Ghirapur Gridworks has an extra 82.85 Copper
E13: Copper Ore | F13: 900 | G13: Miner | J13: Copper Ingots | K13: =2250-K14-K15-K16-K17-K18-K19-K20 -> 99.690889 | L13: Available
E14: Water | F14: 600 | G14: Water Extractor | J14: Copper Ingots | K14: 142.5 | L14: Neko's Nexus | M14: Top Right
J15: Copper Ingots | K15: 104.65 | L15: Ghirapur Gridworks | M15: Top Right
J16: Copper Ingots | K16: 113.833 | L16: The Abyssal Chains of Shandalar | M16: Bottom Left | O16: Bottom left belt going to The Abyssal Chains of shandalar has an extra 366.1666 Copper Ingots
J17: Copper Ingots | K17: 246.67 | L17: Riverteers District | M17: Bottom Right
J18: Copper Ingots | K18: 1272.67 | L18: Phyrexian Datavault
J19: Copper Ingots | K19: 13.2 | L19: Keldon Armory
J20: Copper Ingots | K20: =226.8+29+71/72 -> 256.78611 | L20: Tollarian Meltdown
O21: On the desert
O23: Top belt going to Riveteers, Phyrexian Datavault district and Keldon Armory has an extra 103.46666 Copper
O27: Bottom belt going to Phyrexian Datavault district has an extra 79.017 Copper
O31: Middle belt going to Phyrexian Datavault district has an extra 174 Copper
O35: Rest Belt has an extra 99.690888889

Sheet Thran Foundry
B2: Name | C2: Thran Foundry
B3: Parents | C3: Darksteel Forge
B4: Children | C4: Neko's Nexus, Obelisk of Alara, Karn's Conduit, Thassa's Pulse, Tollarian Meltdown, Simic Subline
B5: Power Production | C5: 0 Mw
B6: Power Consumption | C6: 466.8 MW
B7: Net Gain | C7: -466.8 MW
B8: Storage | C8: 2900 MWh
B9: Cut-Time | C9: 6.21 Hours
E11: Inputs | J11: Outputs
E12: Item | F12: Amount | G12: Source | J12: Item | K12: Amount | L12: Destination | M12: Notes | O12: Top right belt going to Neko's Nexus has an extra 180 steel on it
E13: Iron Ingots | F13: 960 | G13: Darksteel Forge | J13: Steel Ingots | K13: =1440-K14-K15-K16-K17-K18-K19-K20 -> 112.29452 | L13: Available
E14: Coal | F14: 960 | G14: Miners | J14: Steel Ingots | K14: 300 | L14: Neko's Nexus
J15: Steel Ingots | K15: 392.666 | L15: Obelisk of Alara | M15: Bottom Container
J16: Steel Ingots | K16: 110.01 | L16: Karn's Conduit | M16: Bottom Container
J17: Steel Ingots | K17: 40.888 | L17: Thassa's Pulse | M17: Bottom Container
J18: Steel Ingots | K18: ='Tollarian Meltdown'!V21+'Tollarian Meltdown'!V22 -> 214.07037 | L18: Tollarian Meltdown | M18: Top Container
J19: Steel Ingots | K19: =158+22/75 -> 158.29333 | L19: Tollarian Meltdown | M19: Bottom Container | O19: On the desert
J20: Steel Ingots | K20: =111+7/9 -> 111.77778 | L20: Simic Subline | M20: Top Container | O20: Top Container has an extra 34.15185
O23: Bottom Container has an extra 78.14267

Sheet Neko's Nexus
B2: Name | C2: Neko's Nexus
B3: Parents | C3: Darksteel Forge, Xantcha's Crucible, Oran-Rief Mines, Thran Foundry
B4: Children | C4: None
B5: Power Production | C5: 0 Mw
B6: Power Consumption | C6: 805.9 MW
B7: Net Gain | C7: -805.9 MW
B8: Storage | C8: 13.1 GWh
B9: Cut-Time | C9: 16.25 Hours
E10: Inputs | J10: Outputs
E11: Item | F11: Amount | G11: Source | J11: Item | K11: Amount | L11: Destination
E12: Limestone | F12: 480 | G12: Miners | J12: Concrete | K12: 61.6875 | L12: Dimensional Depot
E13: Water | F13: 422.5 | G13: Water Extractors | J13: Steel Beam | K13: 45 | L13: Dimensional Depot
E14: Steel Ingots | F14: 300 | G14: Thran Foundry | J14: Wire | K14: 45 | L14: Dimensional Depot
E15: Copper Ingots | F15: 142.5 | G15: Xantcha's Crucible | J15: Steel Pipes | K15: 33.125 | L15: Dimensional Depot
E16: Iron Ingots | F16: 111.25 | G16: Darksteel Forge | J16: Quickwire | K16: 30 | L16: Dimensional Depot
E17: Caterium Ingots | F17: 18 | G17: Oran-Rief Mines | J17: Cable | K17: 30 | L17: Dimensional Depot
J18: Screws | K18: 25 | L18: Dimensional Depot
J19: Copper Sheet | K19: 22.5 | L19: Dimensional Depot
J20: Iron Plate | K20: 20.5 | L20: Dimensional Depot
J21: Iron Rods | K21: 15 | L21: Dimensional Depot
J22: Encased Industrial Beams | K22: 7.3125 | L22: Dimensional Depot
J23: Reinforced Iron Plate | K23: 7.25 | L23: Dimensional Depot
J24: Rotors | K24: 5 | L24: Dimensional Depot
J25: Stators | K25: 3 | L25: Dimensional Depot
J26: Motors | K26: 2.5 | L26: Dimensional Depot
J27: Modular Frames | K27: 2.25 | L27: Dimensional Depot
J28: Heavy Modular Frame | K28: 1.4065 | L28: Dimensional Depot
J29: Portable Miners | K29: 0.5 | L29: Dimensional Depot

Sheet Ketria Crystals
B2: Name | C2: Ketria Crystals
B3: Parents | C3: None
B4: Children | C4: Ghirapur Gridworks,Phyrexian Datavault, Keldon Armory, Obelisks of Alara, Simic Subline
B5: Power Production | C5: 0 Mw
B6: Power Consumption | C6: 1108 MW
B7: Net Gain | C7: -1108 MW
B8: Storage | C8: 4300 Wh
B9: Cut-Time | C9: 3.88 Hours
E10: Inputs | J10: Outputs
E11: Item | F11: Amount | G11: Source | J11: Item | K11: Amount | L11: Destination
E12: Raw Quartz | F12: 1380 | G12: Miners | J12: Quartz Crystals | K12: 26.25 | L12: Dimensional Depot
E13: Limestone | F13: 500 | G13: Miners | J13: Silica | K13: 19.444 | L13: Dimensional Depot | N13: Uncompressed Quartz Crystal Line that goes to Ghirapur Gridworks has an extra 189.333
E14: Water | F14: 600 | G14: Water Extractors | J14: Quartz Crystals | K14: =840-K12-K16-K18-K20-K21-K22-K23 -> 206.3723 | L14: Available
J15: Silica | K15: 29.40555 | L15: Available
J16: Quartz Crystals | K16: 54 | L16: Ghirapur Gridworks
J17: Silica | K17: 45.15 | L17: Ghirapur Gridworks | N17: Uncompressed Silica Line that goes to Ghirapur Gridworks has an extra 155.40555
J18: Quartz Crystals | K18: 300 | L18: Phyrexian Datavault
J19: Silica | K19: 606 | L19: Phyrexian Datavault
J20: Quartz Crystals | K20: 15 | L20: Keldon Armory
J21: Quartz Crystals | K21: 72 | L21: Obelisk of Alara
J22: Quartz Crystals | K22: 146.3777 | L22: Tollarian Meltown | N22: On the desert
J23: Quartz Crystals | K23: 20 | L23: Simic Subline
N24: Quartz Crystal Line going to Phyrexian Datavault, Keldon Armory, Simic Subline, Tollarian Meltdown and Obelisks of Alara has an extra 206.3723
N28: Silica Line going to Phyrexian Datavault has an extra 29.40555

Sheet Ghirapur Gridworks
B2: Name | C2: Ghirapur Gridworks
B3: Parents | C3: None
B4: Children | C4: None
B5: Power Production | C5: 0 Mw
B6: Power Consumption | C6: 357.9 MW
B7: Net Gain | C7: -357.9 MW
B8: Storage | C8: 2400 MWh
B9: Cut-Time | C9: 6.70 Hours
E10: Inputs | J10: Outputs
E11: Item | F11: Amount | G11: Source | J11: Item | K11: Amount | L11: Destination
E12: Caterium Ingots | F12: 18 | G12: Oran-Rief Mines | J12: Crystal Oscilators | K12: 1.5 | L12: Dimensional Depot
E13: Iron Ingots | F13: 37.5 | G13: Darksteel Forge | J13: High-Speed Connectors | K13: 1.5 | L13: Dimensional Depot
E14: Water | F14: 37.65 | G14: Water Extractors | J14: AI Limiters | K14: 2.25 | L14: Dimensional Depot
E15: Silica | F15: 45.15 | G15: Ketria Crystals | J15: Computers | K15: 3 | L15: Dimensional Depot
E16: Quartz Crystals | F16: 54 | G16: Ketria Crystals | J16: Circuit Boards | K16: 6 | L16: Dimensional Depot
E17: Copper Ingots | F17: 104.65 | G17: Ketria Crystals

Sheet The Abyssal Chains of Shandalar
B2: Name | C2: The Abyssal Chains of Shandalar
B3: Parents | C3: Darksteel Forge, Xantcha's Crucible, Kaladesh Refinery
B4: Children | C4: None
B5: Power Production | C5: 0 Mw
B6: Power Consumption | C6: 231.9 MW
B7: Net Gain | C7: -231.9 MW
B8: Storage | C8: 14.7 GWh
B9: Cut-Time | C9: 63.39 Hours
E10: Inputs | J10: Outputs
E11: Item | F11: Amount | G11: Source | J11: Item | K11: Amount | L11: Destination
E12: Limestone | F12: 18.75 | G12: Miners | J12: Adaptive Control Units | K12: 0.5 | L12: Dimensional Depot
E13: Water | F13: 28.625 | G13: Water Extractors | J13: Modular Engines | K13: 0.5 | L13: Dimensional Depot
E14: Copper Ingots | F14: 113.833 | G14: Xantcha's Crucible
E15: Iron Ingots | F15: 234.25 | G15: Darksteel Forge
E16: Plastic | F16: 42 | G16: Kaladesh Refinery
E17: Rubber | F17: 7.5 | G17: Kaladesh Refinery

Sheet Kaladesh Refinery
B2: Name | C2: Kaladesh Refinery
B3: Parents | C3: None
B4: Children | C4: Phyrexian Datavault, The Abyssal Chains of Shandalar, Keldon Armory, Obelisks of Alara, Tollarian Meltdown, Simic Subline, Aetherflux Reactor, The Interplanar Beacon
B5: Power Production | C5: 0 Mw
B6: Power Consumption | C6: 2217.5 MW
B7: Net Gain | C7: -2217.5 MW
B8: Storage | C8: 8800 MWh
B9: Cut-Time | C9: 3.96 Hours
E10: Inputs | J10: Outputs
E11: Item | F11: Amount | G11: Source | J11: Item | K11: Amount | L11: Destination | M11: Belt
E12: Crude Oil | F12: 300 | G12: Oil Extractor | J12: Rubber | K12: 25 | L12: Dimensional Depot
E13: Water | F13: 1000 | G13: Water | J13: Rubber | K13: =500-K12-K16-K18-K20-K21-K22-K23 -> 28.74549 | L13: The Interplanar Beacon
J14: Plastic | K14: =390-K17-K19-K24 -> 30.833333 | L14: Available
J15: Empty Canisters | K15: 20 | L15: Dimensional Depot
J16: Rubber | K16: 7.5 | L16: The Abyssal Chains of Shandalar | O16: Plastic Belt going to the Abyssal Chains of Shandalar (Middle) has an extra 348 Plastic
J17: Plastic | K17: 42 | L17: The Abyssal Chains of Shandalar
J18: Rubber | K18: 210 | L18: Phyrexian Datavault
J19: Plastic | K19: 280 | L19: Phyrexian Datavault
J20: Rubber | K20: 2.8 | L20: Keldon Armory
J21: Rubber | K21: 109.5 | L21: Obelisks of Alara | O21: On the desert
J22: Rubber | K22: =79+19/50+23+19/255 -> 102.45451 | L22: Tollarian Meltdown
J23: Rubber | K23: 14 | L23: Simic Subline
J24: Plastic | K24: =34+2/3+2.5 -> 37.166667 | L24: Aetherflux Reactor
O27: Plastic Line going to Phyrexian Datavault has an extra 33.333

Sheet Riveteers District
B2: Name | C2: Riveteers District
B3: Parents | C3: Xantcha's Crucible
B4: Children | C4: Phyrexian Datavault, Keldon Armory, Jund Pyroclast, Urabrask's Refinery, Obelisks of Alara, Karn's Conduit, Tollarian Meltdown. Aetherflux Reactor, The Interplanar Beacon
B5: Power Production | C5: 0 Mw
B6: Power Consumption | C6: 1760.5 MW
B7: Net Gain | C7: -1760.5
B8: Storage | C8: 7300 MWh
B9: Cut-Time | C9: 4.14 Hours
E10: Inputs | J10: Outputs
E11: Item | F11: Amount | G11: Source | J11: Item | K11: Amount | L11: Destination
E12: Bauxite | F12: 600 | G12: Miners | J12: Alclcad Aluminum Sheet | K12: 49.333 | L12: Dimensional Depot
E13: Limestone | F13: 1000 | G13: Miners | J13: Alclcad Aluminum Sheet | K13: =246+2/3-K28-K30 -> 26.333333 | L13: Available
E14: Coal | F14: 400 | G14: Miners | J14: Aluminum Scrap | K14: 12 | L14: Dimensional Depot
E15: Sulfur | F15: 200 | G15: Miners | J15: Aluminum Ingots | K15: 45 | L15: Dimensional Depot
E16: Water | F16: 240 | G16: Water Exctractors | J16: Aluminum Casing | K16: =222-K19-K22-K25-K29 -> 20.1375 | L16: Dimensional Depot
E17: Copper Ingots | F17: 246.67 | G17: Xantcha's Crucible | J17: Silica | K17: 7.35 | L17: Keldon Armory
J18: Silica | K18: =410-K17-K23-K24-K26-K27 -> 89.898889 | L18: Available
J19: Aluminum Casing | K19: 160 | L19: Phyrexian Datavault
J20: Empty Fluid Tank | K20: 5 | L20: Dimensional Depot
J21: Aluminum Ingots | K21: 150 | L21: Jund Pyroclast
J22: Aluminum Casing | K22: 0.3 | L22: Keldon Armory
J23: Silica | K23: 176.4 | L23: Obelisks of Alara
J24: Silica | K24: 28.6 | L24: Karn's Conduit
J25: Aluminum Casing | K25: =1+9/16 -> 1.5625 | L25: Jund Pyroclast
J26: Silica | K26: =72+124/225 -> 72.551111 | L26: Tollarian Meltdown
J27: Silica | K27: 35.2 | L27: Simic Subline
J28: Alclad Aluminum Sheet | K28: =114+2/15 -> 114.13333 | L28: Aetherflux Reactor
J29: Aluminum Casing | K29: 40 | L29: The Interplanar Beacon
J30: Alclad Aluminum Sheet | K30: =106+1/5 -> 106.2 | L30: The Interplanar Beacon
L64: =296-49-1/3-K28-90 -> 42.533333
L66: =L64/638*241 -> 16.066667

Sheet Phyrexian Datavault
B2: Name | C2: Phyrexian Datavault
B3: Parents | C3: Kaladesh Refinery, Xantcha's Crucible, Oran-Rief Mines, Ketria Crystals, Riveteers District, Aetherflux Reactor
B4: Children | C4: Karn's Conduit, Thassa's Pulse, Simic Subline, The Interplanar Beacon, Aetherflux Reactor
B5: Power Production | C5: 0 Mw
B6: Power Consumption | C6: 3397.7 MW
B7: Net Gain | C7: -3397.7 MW
B8: Storage | C8: 6000 MWh
B9: Cut-Time | C9: 1.76 Hours
E10: Inputs | J10: Outputs
E11: Item | F11: Amount | G11: Source | J11: Item | K11: Amount | L11: Destination
E12: Copper Ingots | F12: 1272.67 | G12: Xantcha's Crucible | J12: =10-J14-J16-J18 -> 0.5 | K12: Supercomputers | L12: Dimensional Depot
E13: Silica | F13: 606 | G13: Ketria Crystals | J13: =10-J17-J15 -> 1 | K13: Radio Control Units | L13: Dimensional Depot
E14: Quartz Crystals | F14: 300 | G14: Ketria Crystals | J14: 0.5 | K14: Supercomputers | L14: Karn's Conduit
E15: Water | F15: 481 | G15: Water Extractors | J15: 2 | K15: Radio Control Units | L15: Thassa's Pulse
E16: Rubber | F16: 210 | G16: Kaladesh Refinery | J16: 1 | K16: Supercomputers | L16: Simic Subline
E17: Plastic | F17: 280 | G17: Kaladesh Refinery | J17: 7 | K17: Radio Control Units | L17: Aetherflux Reactor
E18: Caterium Ingots | F18: 158.33 | G18: Oran-Rief Mines | J18: 8 | K18: Supercomputers | L18: The Interplanar Beacon
E19: Aluminum Casing | F19: 160 | G19: Riveteers District

Sheet Jund Pyroclast
B2: Name | C2: Jund Pyroclast
B3: Parents | C3: Riveteers District, Darksteel Forge, Oran-Rief Mines
B4: Children | C4: Obelisks of Alara
B5: Power Production | C5: 18917.3 Mw
B6: Power Consumption | C6: 2019.5 MW
B7: Net Gain | C7: 17042.1 MW
B8: Storage | C8: 3000 MWh
B9: Cut-Time | C9: Infinite
E10: Inputs | J10: Outputs
E11: Item | F11: Amount | G11: Source | J11: Item | K11: Amount | L11: Destination
E12: Water | F12: 986.67 | G12: Water Extractors | J12: 29.17 | K12: Plastic | L12: Available
E13: Nitrogen Gas | F13: 300 | G13: Extractor | J13: 6.25 | K13: Polymer Resin | L13: Dimensional Depot
E14: Oil | F14: 150 | G14: Oil Extractor | J14: 12.5 | K14: Compacted Coal | L14: Dimensional Depot
E15: Aluminum Ingots | F15: 150 | G15: Riveteers District | J15: =150-J16-J19 -> 138.5 | K15: Packaged Rocket Fuel | L15: Dimensional Depot
E16: Sulfur | F16: 400 | G16: Miner | J16: 3.13 | K16: Packaged Rocket Fuel | L16: Obelisks of Alara
E17: Coal | F17: 212.5 | G17: Miner | J17: =1+9/16 -> 1.5625 | K17: Gas Filter | L17: Dimensional Depot
E18: Iron Ingots | F18: =9+3/8 -> 9.375 | G18: Darksteel Forge | J18: =1+9/16 -> 1.5625 | K18: Iodine-Infused Filter | L18: Dimensional Depot
E19: Caterium Ingots | F19: 2.5 | G19: Oran-Rief Mines | J19: 8.37 | K19: Packaged Rocket Fuel | L19: Tollarian Meltdown
E20: Aluminum Casing | F20: =1+9/16 -> 1.5625 | G20: Riveteers District

Sheet Keldon Armory
D4: Name | E4: Keldon Armory
D5: Parents | E5: Kaladesh Refinery, Riveteers District, Oran-Rief Mines, Xantcha's Crucible, Ketria Crystals, Darksteel Forge, Tollarian Meltdown
D6: Children | E6: Karn's Conduit, Tollarian Meltdown, The Interplanar Beacon
D7: Power Production
D8: Power Consumption | E8: 1390.1 MW
D9: Net Gain | E9: -1390.1 MW
D10: Storage | E10: 2200 MWh
D11: Cut-Time | E11: Infinite
G12: Inputs | K12: Outputs
G13: Item | H13: Amount | I13: Source | K13: Item | L13: Amount | M13: Destination
G14: Aluminum Casing | H14: 0.3 | I14: Riveteers District | K14: Nobelisk | L14: 2 | M14: Dimensional Depot
G15: Rubber | H15: 2.8 | I15: Kaladesh Refinery | K15: Pulse Nobelisk | L15: 2 | M15: Dimensional Depot
G16: Silica | H16: 7.35 | I16: Riveteers District | K16: Cluster Nobelisk | L16: 2 | M16: Dimensional Depot
G17: Caterium Ingots | H17: 9.6 | I17: Oran-Rief Mines | K17: Black Powder | L17: 2.5 | M17: Dimensional Depot
G18: Copper Ingots | H18: 13.2 | I18: Xantcha's Crucible | K18: Smokeless Powder | L18: 2.5 | M18: Dimensional Depot
G19: Quartz Crystals | H19: 15 | I19: Ketria Crystals | K19: Rifle Ammo | L19: 5 | M19: Dimensional Depot
G20: Sulfur | H20: 30.4666 | I20: Miner (Jund Pyroclast) | K20: Homing Rifle Ammo | L20: 5 | M20: Dimensional Depot
G21: Coal | H21: 30.4666 | I21: Miner (Jund Pyroclast) | K21: Turbo Rifle Ammo | L21: 5 | M21: Dimensional Depot
G22: Iron Ingots | H22: 150 | I22: Darksteel Forge | K22: Iron Rebar | L22: 5 | M22: Dimensional Depot
G23: Oil | H23: 150 | I23: Oil Extractor | K23: Shatter Rebar | L23: 5 | M23: Dimensional Depot
G24: Water | H24: 461.41666 | I24: Water Extractor | K24: Stun Rebar | L24: 5 | M24: Dimensional Depot
K25: Explosive Rebar | L25: 5 | M25: Dimensional Depot
K26: Packaged Turbo Fuel | L26: 5 | M26: Dimensional Depot
K27: Packaged Fuel | L27: 11.41666 | M27: Dimensional Depot
K28: Plastic | L28: 46 | M28: Karn's Conduit
K29: Plastic | L29: =391+77/120-L30-L28-L33 -> 115.62947 | M29: Available
K30: Plastic | L30: ='Tollarian Meltdown'!F21 -> 191.5122 | M30: Tollarian Meltdown
K31: Black Powder | L31: 2.5 | M31: Tollarian Meltdown
K32: Smokeless Powder | L32: 2.5 | M32: Tollarian Meltdown
K33: Plastic | L33: 38.5 | M33: The Interplanar Beacon

Sheet Urabrask's Refinery
B2: Name | C2: Urabrask's Refinery
B3: Parents | C3: Riveteers District
B4: Children | C4: Obelisks of Alara, Thassa's Pulse, Tollarian Meltdown, Aetherflux Reactor, Ydris’ Nexus
B5: Power Production | C5: 0 MW
B6: Power Consumption | C6: 4352.7 MW | F6: =5800/4352.7 -> 1.3325063
B7: Net Gain | C7: -4352.7 MW
B8: Storage | C8: 5800 MWh
B9: Cut-Time | C9: 1.33 Hours
E10: Inputs | J10: Outputs
E11: Item | F11: Amount | G11: Source | J11: Item | K11: Amount | L11: Destination
E12: Limestone | F12: 2214.285 | G12: Miner | J12: =2480-J13-J14-J15-J16-J17-J18 -> 57.411111 | K12: Aluminum Ingots | L12: Available
E13: Sulfur | F13: 620 | G13: Miner | J13: 515 | K13: Aluminum Ingots | L13: Obelisks of Alara | N13: Line | O13: Available
E14: Raw Quartz | F14: 1148.5714 | G14: Miner | J14: =66+2/3 -> 66.666667 | K14: Aluminum Ingots | L14: Thassa's Pulse | N14: 1 | O14: 0
E15: Raw Quartz | F15: 180 | G15: Riveteers District Miner | J15: =734+32/45 -> 734.71111 | K15: Aluminum Ingots | L15: Tollarian Meltdown | N15: 2 | O15: =J12 -> 57.411111
E16: Coal | F16: 1240 | G16: Miner | J16: =543+28/45 -> 543.62222 | K16: Aluminum Ingots | L16: The Mirrodin Trigon | N16: 3 | O16: 0
E17: Water | F17: 744 | G17: Miner | J17: 281.7 | K17: Aluminum Ingots | L17: Ydris’ Nexus | N17: 4 | O17: 0
E18: Bauxite | F18: 1680 | G18: Miner | J18: =280 + 8/9 -> 280.88889 | K18: Aluminum Ingots | L18: Aetherflux Reactor
E19: Bauxite | F19: 180 | G19: Riveteers District Miner

Sheet Obelisks of Alara 
B2: Name | C2: Obelisks of Alara
B3: Parents | C3: Riveteers District, Ketria Crystals, Thran Foundry, Oran-Rief Mines, Urabrask's Refinery
B4: Children
B5: Power Production
B6: Power Consumption | C6: 3371.9 MW
B7: Net Gain | C7: -3371.9 MW
B8: Storage | C8: 45.8 GWh
B9: Cut-Time | C9: 13.58 Hours
E10: Inputs | J10: Outputs
E11: Item | F11: Amount | G11: Source | J11: Item | K11: Amount | L11: Destination
E12: Iron ore | F12: 485.50555 | G12: Miners | J12: 5 | K12: Heat Sink | L12: Dimensional Depot
E13: Limestone | F13: 461.4 | G13: Miners | J13: 2.5 | K13: Smart Plating | L13: Dimensional Depot
E14: Copper Ore | F14: 421.33889 | G14: Miners | J14: 2 | K14: Fused Modular Frame | L14: Dimensional Depot
E15: Silica | F15: 176.4 | G15: Riveteers District | J15: 2 | K15: Turbo Motor | L15: Dimensional Depot
E16: Quartz Crystal | F16: 72 | G16: Ketria Crystals | J16: 2 | K16: Cooling System | L16: Dimensional Depot
E17: Water | F17: 599.9 | G17: Water Extractors | J17: 1 | K17: Thermal Propulsion Rocket | L17: Dimensional Depot
E18: Steel Ingot | F18: 392.6666 | G18: Thran Foundry
E19: Rubber | F19: 109.5 | G19: Kaladesh Refinery
E20: Caterium Ingot | F20: 72 | G20: Oran-Rief Mines
E21: Aluminum Ingot | F21: 515 | G21: Urabrask's Refinery
E22: Packaged Rocket Fuel | F22: =1.55+1.58 -> 3.13 | G22: Jund Pyroclast

Sheet Karn's Conduit
B2: Name | C2: Karn's Conduit
B3: Parents | C3: Obelisks of Alara, Keldon Armory, Riveteers District, Phyrexian Datavault, Thran Foundry , Darksteel Forge
B4: Children
B5: Power Production
B6: Power Consumption | C6: 738.9 MW
B7: Net Gain | C7: -738.9 MW
B8: Storage | C8: 2800 MWh
B9: Cut-Time | C9: 3.78 Hours
E10: Inputs | J10: Outputs
E11: Item | F11: Amount | G11: Source | J11: Item | K11: Amount | L11: Destination
E12: Iron Ingots | F12: 12.0138 | G12: Darksteel Forge | J12: Versatile Framework | K12: =5/8 -> 0.625 | L12: Dimensional Depot
E13: Limestone | F13: 138.0125 | G13: Mk3 Miner | J13: Automated Wiring | K13: 1 | L13: Dimensional Depot
E14: Copper Ore | F14: 98.2437 | G14: Obelisks Of Alara Miner | J14: Assembly Director System | K14: 0.5 | L14: Dimensional Depot
E15: Silica | F15: 28.6 | G15: Riveteers District | J15: Electromagnetic Control Rods | K15: 3.5 | L15: Dimensional Depot
E16: Water | F16: 209.1062 | G16: Water Extractor | J16: Magnetic Field Generator | K16: 0.5 | L16: Dimensional Depot
E17: Steel Ingot | F17: 110.01 | G17: Thran Foundry
E18: Plastic | F18: 46 | G18: Keldon Armory
E19: Caterium Ingot | F19: 5 | G19: Oran-Rief Mines
E20: Supercomputer | F20: 0.5 | G20: Phyrexian Datavault

Sheet Thassa's Pulse
B2: Name | C2: Thassa's Pulse
B3: Parents | C3: Riveteers District, Phyrexian Datavault, Urabrask's Refinery, Thran Foundry, Jund Pyroclast
B4: Children
B5: Power Production
B6: Power Consumption Stable | C6: 945.7 MW
B7: Storage Stable | C7: 1600 MWh
B8: Cut-Time Stable | C8: 1.69 Hours
B9: Power Consumption Unstable | C9: 702.15 MW
B10: Storage Unstable | C10: 2000 MWh
B11: Cut-Time Unstable | C11: 2.84 Hours
E13: Inputs | J13: Outputs
E14: Item | F14: Amount | G14: Source | J14: Item | K14: Amount | L14: Destination
E15: Radio Control Units | F15: 2 | G15: Phyrexian Datavault | J15: Copper Powder | K15: 20 | L15: Dimensional Depot
E16: Iron Ore | F16: 0.8888 | G16: Miner | J16: Pressure Conversion Cube | K16: 0.5 | L16: Dimensional Depot
E17: Nitrogen Gas | F17: 25 | G17: Jund Pyroclast Well | J17: Nuclear Pasta | K17: 0.5 | L17: Dimensional Depot
E18: Steel Ingots | F18: 40.8888 | G18: Thran Foundru
E19: Aluminum Ingots | F19: 66.6666 | G19: Urabrask's Refinery
E20: Limestone | F20: 72.8 | G20: Riveteers District Miner
E21: Water | F21: 263.1358 | G21: Water Extractor
E22: Copper Ore | F22: 303.7037 | G22: Miners

Sheet Tollarian Meltdown
B2: Name | C2: Tollarian Meltdown
B3: Parents | C3: Riveteers District , Keldon Armory, Kaladesh Refinery, Ketria Crystals, Thran Foundry, Xantcha's Crucible, Darksteel Forge, Thassa's Pulse, Keldon Armory, Phyrexian Datavault, Jund Pyroclast
B4: Children | C4: The Interplanar Beacon
B5: Power Production Stable | C5: 86953.125
B6: Power Consumption Stable | C6: 14379.4 MW
B7: Storage Stable | C7: 3100 MWh
B8: Cut-Time Stable | C8: Infinite
B9: Net Gain Stable | C9: 72573.725
B10: Power Production Unstable | C10: 52171.875
B11: Power Consumption Unstable | C11: 5530.95 MW
B12: Net Gain Unstable | C12: 46640.925
B13: Storage Unstable | C13: 5600 MW
B14: Cut-Time Unstable | C14: Infinite
E18: Inputs | K18: Outputs | O18: Water Distribution | V18: Steel Distribution | AA18: Machine | AB18: Amount | AC18: Consumption | AD18: Zone | AE18: Making | AF18: Destiny
E19: Item | F19: Amount | G19: Source | H19: Notes | K19: Item | L19: Amount | M19: Destination | O19: Pipe 1 | Q19: Pipe 2 | S19: Pipe 3 | V19: Top Container | X19: Bottom Container | AA19: Constructor | AB19: 1 | AC19: 0.2 | AD19: Zone A Middle | AE19: Steel Pipe | AF19: Nobelisk
E20: Sulfur | F20: 348.18 | G20: Riveteers District Miner | K20: Silica | L20: =741-L34 -> 688.2 | M20: Available | O20: Amount | P20: Destination | Q20: Amount | R20: Destination | S20: Amount | T20: Destination | V20: Amount | W20: Destination | X20: Amount | Y20: Destination | AA20: Constructor | AB20: 1 | AC20: 0.2 | AD20: Zone A East | AE20: Empty Canisters | AF20: Packagers
E21: Plastic | F21: =186.2622+5.25 -> 191.5122 | G21: Keldon Armory | K21: Rubber | L21: =101+1/15 -> 101.06667 | M21: The Interplanar Beacon | O21: =127+23/40 -> 127.575 | P21: Concrete | Q21: =151+157/225 -> 151.69778 | R21: Concrete | S21: 240 | T21: Caterium Ingots | V21: 170.1 | W21: Steel Pipes for Stators | X21: =158+22/75 -> 158.29333 | Y21: Steel Pipes for Encased Industrial Beams and HMF | AA21: Packager | AB21: 1 | AC21: 0.2 | AD21: Zone A East | AE21: Packaged Water | AF21: Output
E22: Rubber | F22: =79+19/50+23+19/255 -> 102.45451 | G22: Kaladesh Refinery | K22: Time Crystal | L22: 11.52 | M22: Dimensional Depot | O22: =125+29/50 -> 125.58 | P22: Sulfuric Acid | Q22: =148+2/5 -> 148.4 | R22: Concrete | S22: 160 | T22: Copper Ingots | V22: =43+131/135 -> 43.97037 | W22: Steel Pipes for Modular Frames | AA22: Packager | AB22: 1 | AC22: 0.3 | AD22: Zone A East | AE22: Packaged Sulfuric Acid | AF22: Output
E23: Quartz Crystals | F23: 146.3777 | G23: Ketria Crystals | K23: Petroleum Coke | L23: 10 | M23: Dimensional Depot | O23: 2.73 | P23: Water Packager | Q23: 226.8 | R23: Nitric Acid | AA23: Constructor | AB23: 1 | AC23: 0.3 | AD23: Zone B Close to Power Plant | AE23: Empty fluid Tank | AF23: Packagers
E24: Limestone | F24: 153.09 | G24: Riveteers District Miner | K24: Packaged Nitrogen Gas | L24: 5 | M24: Dimensional Depot | O24: =116+92/1125 -> 116.08178 | P24: Copper Ingots | AA24: Packager | AB24: 1 | AC24: 0.4 | AD24: Zone B Close to Power Plant | AE24: Packaged Nitrogen Gas | AF24: Output
E25: Steel Ingots | F25: =V21+V22 -> 214.07037 | G25: Thran Foundry | H25: Coming from Top Container | K25: Plutonium Fuel Rods | L25: =4+64/75 -> 4.8533333 | M25: Aetherflux Reactor | O25: =72+124/225 -> 72.551111 | P25: Copper Sheets | AA25: Refinery | AB25: 1 | AC25: 0.6 | AD25: Zone A East | AE25: Sulfuric Acid | AF25: Packaging
E26: Copper Ingots | F26: =226.8+29+71/72 -> 256.78611 | G26: Xantcha's Crucible | K26: Packaged Nitric Acid | L26: 4.2 | M26: Dimensional Depot | AA26: Packager | AB26: 1 | AC26: 0.7 | AD26: Zone B Close to Power Plant | AE26: Packaged Nitric Acid | AF26: Output
E27: Iron Ingots | F27: =628+1243/3645 -> 628.34102 | G27: Darksteel Forge | K27: Packaged Water | L27: 2.73 | M27: Dimensional Depot | AA27: Assemblers | AB27: 1 | AC27: 1 | AD27: Zone A Middle | AE27: Nobelisk | AF27: Nuke Nobelisk
E28: Copper Ore | F28: =174+46/375 -> 174.12267 | G28: Thassa's Pulse Miner | K28: Packaged Sulfuric Acid | L28: 2.73 | M28: Dimensional Depot | V28: Total | W28: =SUM(V21:V22) -> 214.07037 | X28: Total | Y28: =SUM(X21:X27) -> 158.29333 | AA28: Smelter | AB28: 1 | AC28: 1.2 | AD28: Zone A East | AE28: Caterium Ingots | AF28: Quickwire
E29: Silica | F29: =72+124/225 -> 72.551111 | G29: Riveteers District | K29: Diamonds | L29: 1.54 | M29: Dimensional Depot | O29: Total | P29: =SUM(O21:O28) -> 444.51789 | Q29: Total | R29: =SUM(Q21:Q28) -> 526.89778 | S29: Total | T29: =SUM(S21:S28) -> 400 | V29: Super Total | W29: =W28+Y28 -> 372.3637 | AA29: Assemblers | AB29: 1 | AC29: 1.6 | AD29: Zone A East | AE29: AI Limiter | AF29: Nuke Nobelisk
E30: Aluminum Ingots | F30: =734+32/45 -> 734.71111 | G30: Urabrask's Refinery | K30: Encased Uranium Cell | L30: 1 | M30: Dimensional Depot | O30: Percentage | P30: =P29/600 -> 0.74086315 | Q30: Percentage | R30: =R29/600 -> 0.87816296 | S30: Percentage | T30: =T29/600 -> 0.66666667 | AA30: Constructors | AB30: 2 | AC30: 2.7 | AD30: Zone B | AE30: Iron Plates | AF30: Reinfornced Iron Plates
E31: Caterium Ore | F31: =479+73/600 -> 479.12167 | G31: Miner | K31: Nuke Nobelisk | L31: 0.25 | M31: Dimensional Depot | AA31: Constructors | AB31: 4 | AC31: 2.8 | AD31: Zone A East | AE31: Steel Pipes | AF31: Rotors
E32: Black Powder | F32: 2.5 | G32: Keldon Armory | K32: Uranium Fuel Rod | L32: 0.21 | M32: Dimensional Depot | AA32: Constructors | AB32: 12 | AC32: 3.2 | AD32: Zone A East | AE32: Wire | AF32: Rotors
E33: Smokeless Powder | F33: 2.5 | G33: Keldon Armory | K33: Plutonium Fuel Rods | L33: =7/75 -> 0.093333333 | M33: Dimensional Depot | AA33: Constructors | AB33: 3 | AC33: 3.3 | AD33: Zone B | AE33: Wire | AF33: Reinfornced Iron Plates
E34: Limestone | F34: 1360.1173 | G34: Miners | K34: Silica | L34: =52+4/5 -> 52.8 | M34: The Interplanar Beacon | AA34: Constructor | AB34: 14 | AC34: 3.4 | AD34: Zone A East | AE34: Quickwire | AF34: AI Limiter
E35: Steel Ingots | F35: =X21 -> 158.29333 | G35: Thran Foundry | H35: Coming From Bot Container | AA35: Constructors | AB35: 16 | AC35: 3.7 | AD35: Zone A Middle | AE35: Wire | AF35: Stators
E36: Suflur | F36: 480 | G36: Jund Pyroclast & Urabrask Refinery Miner | AA36: Constructors | AB36: 4 | AC36: 3.7 | AD36: Zone B Close to Power Plant | AE36: Iron Plates | AF36: Nitric Acid
E37: Copper Ore | F37: 240 | G37: Miner | AA37: Assemblers | AB37: 1 | AC37: 4.6 | AD37: Zone A East | AE37: AI Limiter | AF37: Crystal Oscillator
E38: Water | F38: =14727+1247/3000 -> 14727.416 | G38: Water Extractors | AA38: Assemblers | AB38: 8 | AC38: 10.6 | AD38: Zone A East | AE38: AI Limiter | AF38: Crystal Oscillator and Electromagnetic Control Rods
E39: Nitrogen Gas | F39: =1050+13/15 -> 1050.8667 | G39: Well Extractor | AA39: Assemblers | AB39: 1 | AC39: 11.2 | AD39: Zone A East | AE39: Quickwire | AF39: Ai Limiter
E40: Oil | F40: 300 | G40: Oil extractor | AA40: Assemblers | AB40: 6 | AC40: 11.3 | AD40: Zone A East | AE40: Alclad Casing | AF40: Everywhere
E41: Packaged Rocket Fuel | F41: 8.73 | G41: Jund Pyroclast | AA41: Assemblers | AB41: 5 | AC41: 11.6 | AD41: Zone B | AE41: Encased Industrial Beam | AF41: Heavy Modular Frames
E42: Raw Quartz | F42: 600 | G42: Miner | AA42: Assemblers | AB42: 12 | AC42: 11.6 | AD42: Power Plant | AE42: Plutonium Fuel Rod | AF42: Output
AA43: Foundries | AB43: 4 | AC43: 11.7 | AD43: Zone B | AE43: Steel Pipes | AF43: Heavy modular Frames and encased industrial beams
AA44: Assemblers | AB44: 4 | AC44: 12.7 | AD44: Zone A East | AE44: Circuit Boards | AF44: Radio Control Units
...

Sheet The Mirrodin Trigon
B2: Name | C2: The Mirrodin Trigon
B3: Parents | C3: Darksteel Forge, Tollarian Meltdown, Urabrask Refinery
B4: Children | C4: Simic Subline, Aetherflux Reactor
B5: Power Production
B6: Power Consumption Stable | C6: 2933.7 MW
B7: Storage Stable | C7: 4600 MWh
B8: Cut-Time Stable | C8: 1.56 Hours
B9: Power Consumption Unstable | C9: 3449.1 MW (Avg)
B10: Storage Unstable | C10: 5700 MWh
B11: Cut-Time Unstable | C11: 1.65 Hours
B12: Train Color 1 | C12: 5A0069
B13: Train Color 2 | C13: 320249
E15: Inputs | J15: Outputs
E16: Item | F16: Amount | G16: Source | H16: Notes | J16: Item | K16: Amount | L16: Destination
E17: Iron Ingots | F17: =41+47/54 -> 41.87037 | G17: Darksteel Forge | H17: Bottom Container | J17: SAM | K17: 5 | L17: Dimensional Depot
E18: SAM | F18: 3000 | G18: Miners | J18: Reanimated SAM | K18: 1.75 | L18: Dimensional Depot
E19: Water | F19: =1221+113/135 -> 1221.837 | G19: Water Extractors | J19: Ficsite Ingot | K19: 2.91 | L19: Dimensional Depot
E20: Caterium Ore | F20: 1200 | G20: Miners | J20: SAM Fluctuator | K20: 2.83 | L20: Dimensional Depot
E21: Caterium Ore | F21: =21+113/135 -> 21.837037 | G21: Tollarian Meltdown Miner | J21: Ficsite Trigon | K21: =857+17/90-K22-K23 -> 17.188889 | L21: Dimensional Depot
E22: Aluminum Ingot | F22: =543+28/45 -> 543.62222 | G22: Urabrask Refinery | J22: Ficsite Trigon | K22: 80 | L22: Simic Subline
J23: Ficsite Trigon | K23: 760 | L23: Aetherflux Reactor

Sheet Simic Subline
B3: Name | C3: Simic Subline
B4: Parents | C4: Oran-Rief Mines, Ketria Crystals, Kaladesh Refinery, Riveteers District, Thran Foundry, Darksteel Forge, Phyrexian Datavault
B5: Children
B6: Power Production
B7: Power Consumption | C7: 1047.7 MW
B8: Net Gain | C8: -1047.7 MW
B9: Storage | C9: 2300 MWh
B10: Cut-Time | C10: 2.195 Hours
E11: Inputs | J11: Outputs
E12: Item | F12: Amount | G12: Source | H12: Comments | J12: Item | K12: Amount | L12: Destination
E13: Supercomputers | F13: 1 | G13: Phyrexian Datavault | J13: Biochemical Sculptor | K13: 4 | L13: Dimensional Depot
E14: Caterium Ingots | F14: =3+1/3 -> 3.3333333 | G14: Oran-Rief Mines
E15: Rubber | F15: 14 | G15: Kaladesh Refinery
E16: Quartz Crystals | F16: 20 | G16: Ketria Crystals
E17: Iron Ingots | F17: =30+230/243 -> 30.946502 | G17: Darksteel Forge | H17: Bottom Container
E18: Silica | F18: 35.2 | G18: Riveteers District
E19: Ficsite Trigon | F19: 80 | G19: The Mirrodin Trigon
E20: Steel Ingots | F20: =111+7/9 -> 111.77778 | G20: Thran Foundry | H20: Top Container
E21: Iron Ore | F21: =128+1/3 -> 128.33333 | G21: Miner mk3
E22: Copper Ore | F22: =146+31/75 -> 146.41333 | G22: Miner mk3
E23: Limestone | F23: =172+3/5 -> 172.6 | G23: Miner mk3

Sheet Aetherflux Reactor
B2: Name | C2: Aetherflux Reactor
B3: Parents | C3: Tollarian Metldown, Jund Pyroclast, Urabrask Refinery, Kaladesh Refinery, Riveteers District, Phyrexian Datavault, Ydri's Nexus, The Mirrodin Trigon
B4: Children | C4: The Fourfold Furnace, The Interplanar Beacon
B5: Power Consumption Stable | C5: 19,329.2 MW
B6: Storage Stable | C6: 10.6 GW/h
B7: Power Production Stable | C7: 90,625.514 MW
B8: Net gain Stable | C8: 71,296.31 MW
B9: Power Consumption Unstable | C9: 31,929.55 MW.
B10: Storage Unstable | C10: 10.4 GW/h
B11: Power Production Unstable | C11: 90,625.514 MW
B12: Net gain Unstable | C12: 58,695.96 MW
E13: Inputs | J13: Outputs | N13: Unstable Consumptions
E14: Item | F14: Amount | G14: Source | H14: Comments | J14: Item | K14: Amount | L14: Destination | N14: Machine | O14: Amount | P14: Location | Q14: Description | R14: Consumption | S14: Total Consumption
E15: Plutonium Fuel Rods | F15: =4+64/75 -> 4.8533333 | G15: Tollarian Meltdown | J15: Ficsonium Fuel Rods | K15: =364/1215 -> 0.29958848 | L15: Dimensional Depot | N15: Converter | O15: 5 | P15: Power Plant | Q15: Dark Matter Residue for Ficsonium | R15: =(384.6+96.1)/2 -> 240.35 | S15: =R15*O15 -> 1201.75
E16: Reanimated SAM | F16: =242+2/3 -> 242.66667 | G16: Ydris' Nexus | H16: Power Plant | J16: Quartz Crystals | K16: =398+14/75-K41 -> 256.18667 | L16: Available | N16: Quantum Encoder | O16: 10 | P16: Power Plant | Q16: Ficsonium Fuel Rods | R16: =1922.8/2 -> 961.4 | S16: =R16*O16 -> 9614
E17: Water | F17: 11648 | G17: Water Extractors | H17: Plutonium Power Plants | J17: Silica | K17: =537+28/125 -> 537.224 | L17: Available | N17: Particle Accelerator | O17: 5 | P17: Power Plant | Q17: Ficsonium | R17: =(1442.1+480.7)/2 -> 961.4 | S17: =R17*O17 -> 4807
E18: Water | F18: =5752+8/81 -> 5752.0988 | G18: Water Extractors | H18: Ficsonium Power plants | J18: Raw Quartz | K18: 5 | L18: Dimensional Depot | N18: Converter | O18: 10 | P18: Power Plant | Q18: Excited Photonic Matter for Ficsonium Fuel Rods | R18: =(61.5+15.4)/2 -> 38.45 | S18: =R18*O18 -> 384.5
E19: Ficsite Trigons | F19: 760 | G19: The Mirrodin Trigon | H19: Ficsonium Fuel Rods | J19: Limestone | K19: =8+1/3 -> 8.3333333 | L19: Dimensional Depot | N19: Converter | O19: 3 | P19: Trigon Module | Q19: Ficsite Trigons | R19: =(288.1+72)/2 -> 180.05 | S19: =R19*O19 -> 540.15
E20: Aluminum Ingots | F20: =280 + 8/9 -> 280.88889 | G20: Urabrask Refinery | H20: Ficsite Trigons | J20: Iron Ore | K20: 45 | L20: Dimensional Depot | N20: Particle Accelerator | O20: 14 | P20: Singularity Cells Module | Q20: Nuclear Pasta | R20: =(1319.6+439.9)/2 -> 879.75 | S20: =R20*O20 -> 12316.5
E21: Reanimated SAM | F21: =140+4/9 -> 140.44444 | G21: Ydris Nexus | H21: Ficsite Trigons | J21: Iron Ingots | K21: 45 | L21: Dimensional Depot | N21: Particle Accelerator | O21: 2 | P21: Singularity Cells Module | Q21: Diamonds | R21: =(479.9+160)/2 -> 319.95 | S21: =R21*O21 -> 639.9
E22: Caterium Ore | F22: 600 | G22: Miners | H22: 2 Modules | J22: Steel Ingots | K22: =745+71/1350-K42 -> 435.88593 | L22: Available | N22: Converter | O22: 5 | P22: Singularity Cells Module | Q22: Time Crystals | R22: =(374.4+93.6)/2 -> 234 | S22: =R22*O22 -> 1170
E23: Plastic | F23: =34+2/3 -> 34.666667 | G23: Kaladesh Refinery | H23: Electromagnetic Control Rods | J23: Steel Ingots | K23: 5 | L23: Dimensional Depot | N23: Converter | O23: 2 | P23: Singularity Cells Module | Q23: Dark Matter Residue | R23: =(255.9+64)/2 -> 159.95 | S23: =R23*O23 -> 319.9
E24: Water | F24: =597+13/15 -> 597.86667 | G24: Water Extractors | H24: Electromagnetic Control Rods | J24: Aluminum Ingots | K24: =996+25/36-K37-K39-K43 -> 32.927778 | L24: Available | N24: Particle Accelerator | O24: 1 | P24: Singularity Cells Module | Q24: Dark Matter Crystals | R24: =(1403.8+467.9)/2 -> 935.85 | S24: =R24*O24 -> 935.85
E25: Iron Ore | F25: =299+1/15 -> 299.06667 | G25: Miners | H25: Electromagnetic Control Rods | J25: Packaged Alumina Solution | K25: 5 | L25: Dimensional Depot | N25: Total | O25: =SUM(S15:S24) -> 31929.55
E26: Water | F26: =333+1/3 -> 333.33333 | G26: Water Extractors | H26: Silica/Quartz Module | J26: Bauxite | K26: 5 | L26: Dimensional Depot
E27: Raw Quartz | F27: 1800 | G27: Miners | H27: Silica/Quartz Module | J27: Sulfur | K27: 3.75 | L27: Dimensional Depot
E28: Limestone | F28: 2000 | G28: Miners | H28: Silica/Quartz Module | J28: Sulfur | K28: 590 | L28: The Fourfold Furnace
E29: Iron Ore | F29: =367+10/13 -> 367.76923 | G29: Miners | H29: Ingots Module | J29: Battery | K29: 2.5 | L29: Dimensional Depot
E30: Water | F30: =1411+21/52-712-3.75 -> 695.65385 | G30: Water Extractors | H30: Ingots Module | J30: Copper Ore | K30: 30 | L30: Dimensional Depot
E31: Coal | F31: 200 | G31: Riveteers District Miner | H31: Ingots Module | J31: Nitrogen Gas | K31: =1650-158-5/6-K40 -> 1344.7667 | L31: Available
E32: Coal | F32: 1200 | G32: Miners | H32: Ingots Module | J32: Limestone | K32: 194 | L32: Available
E33: Sulfur | F33: 600 | G33: Miners | H33: Ingots Module | J33: Singularity Cells | K33: =15-K44 -> 1 | L33: Dimensional Depot
E34: Bauxite | F34: 1200 | G34: Miners | H34: Ingots Module | J34: Packaged Oil | K34: =14+2/3 -> 14.666667 | L34: Dimensional Depot
E35: Plastic | F35: 2.5 | G35: Kaladesh Refinery | H35: Ingots Module | J35: Coal | K35: 5 | L35: Dimensional Depot
E36: Copper Ore | F36: =226+13834/50625 -> 226.27326 | G36: Miners | H36: 2 Modules | J36: Copper Ingots | K36: 5 | L36: Dimensional Depot
E37: Iron Ore | F37: =30+718/1755 -> 30.409117 | G37: Miners | H37: Fused Modular Frame Module | J37: Aluminum Ingots | K37: 447.5 | L37: The Fourfold Furnace
E38: Water | F38: =17+661/1775+66+3122/6075+385+98/225 -> 469.32186 | G38: Water Extractors | H38: Fused Modular Frame Module | J38: Nitrogen Gas | K38: 442.5 | L38: The Fourfold Furnace
E39: Limestone | F39: =462+392/1125 -> 462.34844 | G39: Miners | H39: Fused Modular Frame Module | J39: Aluminum Ingots | K39: =356+4/15 -> 356.26667 | L39: The Interplanar Beacon
E40: Nitrogen Gas | F40: 1650 | G40: Nitrogen Well | H40: Fused Modular Frame Module | J40: Nitrogen Gas | K40: 146.4 | L40: The Interplanar Beacon
E41: Water | F41: =64+628/1875+57+1/15+93+221/375 -> 214.99093 | G41: Water Extractors | H41: Pressure Conversion Cubes Module | J41: Quartz Crystals | K41: 142 | L41: The Interplanar Beacon
...

Sheet Ydris’ Nexus
B2: Name | C2: Ydris’ Nexus
B3: Parents | C3: Urabrask Refinery, Darksteel Forge
B4: Children | C4: The Fourfold Furnace, Aetherflux Reactor
B5: Power Consumption Stable | C5: 7596.7 MW
B6: Storage Stable | C6: Unknown
B7: Cut-off Time Stable | C7: Unknown
B8: Power Consumption Unstable | C8: 36259.6 MW
B9: Storage Unstable | C9: Unknown
B10: Cut-off Time Unstable | C10: Unknown
E11: Inputs | J11: Outputs | N11: Unstable Consumption
E12: Item | F12: Amount | G12: Source | H12: Comments | J12: Item | K12: Amount | L12: Destination | N12: Machine | O12: Number | P12: Consumption | Q12: Total | R12: Comments
E13: Aluminum Ingot | F13: 281.7 | G13: Urabrask Refinery | J13: Reanimated Sam | K13: =597-K19 -> 142.55556 | L13: The Fourfold Furnace | N13: Particle Accelerator | O13: 9 | P13: 500 | Q13: =P13*O13 -> 4500 | R13: Diamonds at 100%
E14: Iron Ingot | F14: 997.25 | G14: Darksteel Forge | J14: Dark Matter Crystal | K14: 2.25 | L14: Available | N14: Particle Accelerator | O14: 1 | P14: 341 | Q14: =P14*O14 -> 341 | R14: Diamonds at 75%
E15: Oil | F15: =600+600+300+300+150 -> 1950 | G15: Oil Extractors | J15: Time Crystal | K15: 13.2 | L15: The Fourfold Furnace | N15: Converter | O15: 36 | P15: 218.4 | Q15: =P15*O15 -> 7862.4 | R15: Time Crystal
E16: Copper Ore | F16: =367+101/150 -> 367.67333 | G16: Miners | J16: Alien Power Matrix | K16: 0.1 | L16: Dimensional Depot | N16: Particle Accelerator | O16: 4 | P16: =(485.6+1456.8)/2 -> 971.2 | Q16: =P16*O16 -> 3884.8 | R16: Dark Matter Crystal from Superposition Oscillator
E17: Raw Quartz | F17: 1200 | G17: Miners | J17: Quartz Crystal | K17: =6+1/3 -> 6.3333333 | L17: Dimensional Depot | N17: Quantum Encoder | O17: 8 | P17: =1446.2/2 -> 723.1 | Q17: =P17*O17 -> 5784.8 | R17: Superposition Oscillator
E18: SAM | F18: 3600 | G18: Miners | J18: Superposition Oscillator | K18: 1 | L18: Dimensional Depot | N18: Converter | O18: 8 | P18: =(38.8+155.4)/2 -> 97.1 | Q18: =P18*O18 -> 776.8 | R18: Converters for Superposition Oscillator
E19: Water | F19: =911 +176/225 -> 911.78222 | J19: Reanimated Sam | K19: =4090/9 -> 454.44444 | L19: Aetherflux Reactor | N19: Converter | O19: 8 | P19: =(14.1+56.4)/2 -> 35.25 | Q19: =P19*O19 -> 282 | R19: Converter for Power Shards
J20: Dark Matter Crystal | K20: 70 | L20: Aetherflux Reactor | N20: Quantum Encoder | O20: 8 | P20: =1385.4/2 -> 692.7 | Q20: =P20*O20 -> 5541.6 | R20: Power Shards
N21: Particle Accelerator | O21: 4 | P21: =(257.9+773.6)/2 -> 515.75 | Q21: =P21*O21 -> 2063 | R21: Dark matter Crystal from Power Shards
N22: Quantum Encoder | O22: 6 | P22: =1185.7/2 -> 592.85 | Q22: =P22*O22 -> 3557.1 | R22: Alien Power Matrixes
N23: Converter | O23: 2 | P23: =(51.6+206.3)/2 -> 128.95 | Q23: =P23*O23 -> 257.9 | R23: Converters for Alien Power Matrixes
N24: Particle Accelerator | O24: 3 | P24: =(220.7+662.1)/2 -> 441.4 | Q24: =P24*O24 -> 1324.2 | R24: Dark Matter Crystals from Alien Power Matrixes
N25: Sink | O25: 2 | P25: 30 | Q25: =P25*O25 -> 60
N26: Lights | O26: 4 | P26: 6 | Q26: =P26*O26 -> 24
N27: Total | O27: =SUM(Q13:Q26) -> 36259.6

Sheet The Fourfold Furnace
B2: Name | C2: The Fourfold Furnace
B3: Parents | C3: Ydris' Nexus, Aetherflux Reactor
B4: Children | C4: The Interplanar Beacon
B5: Power Consumption Stable | C5: 6,242.8 MW
B6: Storage Stable | C6: 1800 MW/h
B7: Power Production Stable | C7: 40,623.3 MW
B8: Net gain Stable | C8: 34380.5 MW
B9: Power Consumption Unstable | C9: 7803.3 mw
B10: Storage Unstable | C10: 3800 MW/h
B11: Power Production Unstable | C11: 8,635.6 MW
B12: Net gain Unstable | C12: 832.3 MW
E13: Inputs | J13: Outputs | N13: Unstable Consumption
E14: Item | F14: Amount | G14: Source | H14: Comments | J14: Item | K14: Amount | L14: Destination | N14: Machine | O14: Number | P14: Consumption | Q14: Total | R14: Comments
E15: Oil | F15: 600 | G15: Oil Extractors | J15: Rubber | K15: =101+1/15+200+28 + 1901/2550-310 -> 19.812157 | L15: Available | N15: Particle Accelerator | O15: 6 | P15: =(444.1+148)/2 -> 296.05 | Q15: =O15*P15 -> 1776.3 | R15: Coal to Diamonds
E16: Water | F16: =6042+7/8 -> 6042.875 | G16: Water Extractors | J16: Rubber | K16: =200-K15 -> 180.18784 | L16: The Interplanar Beacon | N16: Converters | O16: 12 | P16: =(79.5+318.1)/2 -> 198.8 | Q16: =O16*P16 -> 2385.6 | R16: Diamonds To Time Crystals
E17: SAM | F17: 3600 | G17: Miners | J17: Packaged Ionized Fuel | K17: 5 | L17: Dimensional Depot | N17: Converters | O17: 4 | P17: =(89.8+359.2)/2 -> 224.5 | Q17: =O17*P17 -> 898 | R17: Reanimated Sam to Dark Matter Residue
E18: Time Crystals | F18: 13.2 | G18: Ydris' Nexus | J18: Reanimated Sam | K18: =858+13/72-K19 -> 778.18056 | L18: Available | N18: Particle Accelerator | O18: 3 | P18: =(1152.8+384.3)/2 -> 768.55 | Q18: =O18*P18 -> 2305.65 | R18: Dark Matter Crystals
E19: Reanimated SAM | F19: =142 +5/9 -> 142.55556 | G19: Ydris' Nexus | J19: Reanimated Sam | K19: 80 | L19: The Interplanar Beacon | N19: Converters | O19: 2 | P19: =(346.4+86.6)/2 -> 216.5 | Q19: =O19*P19 -> 433 | R19: Ionized Fuel
E20: Aluminum Ingots | F20: 447.5 | G20: Aetherflux Reactor | N20: Converters | O20: 1 | P20: =(7.6+1.9)/2 -> 4.75 | Q20: =O20*P20 -> 4.75 | R20: Ionized Fuel
E21: Sulfur | F21: 590 | G21: Aetherflux Reactor
E22: Nitrogen Gas | F22: 442.5 | G22: Aetherflux Reactor
E23: Coal | F23: 3600 | G23: Miners
N29: Total | O29: =SUM(Q15:Q20) -> 7803.3

Sheet The Interplanar Beacon
C3: Name | D3: The Interplanar Beacon
C4: Parents | D4: The Fourfold Furnace, Tollarian Meltdown, Kaladesh Refinery, Aetherflux Reactor, Riveteers District, Keldon Armory, Phyrexian Datavault
C5: Children
C6: Power Consumption Stable | D6: 5858 MW
C7: Storage Stable | D7: 7900 MWh
C8: Cut-off Stable | D8: 1.34 Hours
C9: Power Consumption Unstable | D9: 18779.75 MW
C10: Storage Unstable | D10: 19700 MWh
C11: Cut-off Unstable
F12: Inputs | K12: Outputs | O12: Unstable Consumptions
F13: Item | G13: Amount | H13: Source | I13: Module | K13: Item | L13: Amount | M13: Destination | O13: Machine | P13: Amount | Q13: Location | R13: Producing | S13: Destination | T13: Consumption | U13: Total Consumption
F14: Oil | G14: 1200 | H14: Oil Extractor | I14: Time Crystals Module | K14: Time Crystals | L14: =13+7/15 -> 13.466667 | M14: Dimensional Depot | O14: Particle Accelerator | P14: 6 | Q14: Time Crystals Module | R14: Diamonds | S14: Time Crystals | T14: =(250+750)/2 -> 500 | U14: =P14*T14 -> 3000
F15: Water | G15: =270+127+34/65+0.2 -> 397.72308 | H15: Water Extractors | I15: Motors and Rotors Module | K15: Rubber | L15: =310-304.6 -> 5.4 | M15: Dimensional Depot | O15: Converters | P15: 20 | Q15: Time Crystals Module | R15: Time Crystals | S15: 4 Different Places | T15: =(100+400)/2 -> 250 | U15: =P15*T15 -> 5000
F16: Caterium Ore | G16: 127.2 | H16: Miners | I16: Motors and Rotors Module | K16: Ballistic Warp Drives | L16: 2.4 | M16: Dimensional Depot | O16: Converters | P16: 3 | Q16: Final Stage | R16: Excited Photonic Matter | S16: Neural Quantum Processors | T16: =(23.4+93.6)/2 -> 58.5 | U16: =P16*T16 -> 175.5
F17: Iron Ore | G17: =473+27/65 -> 473.41538 | H17: Miners | I17: Motors and Rotors Module | K17: Neural Quantum Processor | L17: 1 | M17: Dimensional Depot | O17: Converters | P17: 3 | Q17: Final Stage | R17: Excited Photonic Matter | S17: Superposition Oscillator | T17: =(39.1+156.5)/2 -> 97.8 | U17: =P17*T17 -> 293.4
F18: Iron Ore | G18: =128+109/117 -> 128.93162 | H18: Miners | I18: Smart Plating Module | K18: AI Expansion Server | L18: 7 | M18: Dimensional Depot | O18: Converters | P18: 3 | Q18: Final Stage | R18: Ficsite Ingot | S18: Ficsite Trigon | T18: =(58.5+234)/2 -> 146.25 | U18: =P18*T18 -> 438.75
F19: Water | G19: =73+79/117 -> 73.675214 | H19: Water Extractors | I19: Smart Plating Module | O19: Quantum Encoder | P19: 2 | Q19: Final Stage | R19: AI Expansion Server | S19: Space Elevator | T19: =1676.4/2 -> 838.2 | U19: =P19*T19 -> 1676.4
F20: Iron Ore | G20: =231+1897/5265 -> 231.3603 | H20: Miners | I20: Heavy Modular Frame Module | O20: Quantum Encoder | P20: 3 | Q20: Final Stage | R20: Superposition Oscillator | S20: 2 Different Places | T20: =1456.4/2 -> 728.2 | U20: =P20*T20 -> 2184.6
F21: Rubber | G21: ='The Fourfold Furnace'!$K$16 -> 180.18784 | H21: The Fourfold Furnace | I21: Several Modules | O21: Quantum Encoder | P21: 3 | Q21: Final Stage | R21: Neural Quantum Processor | S21: 2 Different Places | T21: =1711.6/2 -> 855.8 | U21: =P21*T21 -> 2567.4
F22: Rubber | G22: =101+1/15 -> 101.06667 | H22: Tollarian Meltdown | I22: Several Modules | O22: Particle Accelerator | P22: 1 | Q22: Final Stage | R22: Dark Matter Crystal | S22: Producing 20 without time Crystals | T22: =(500+1500)/2 -> 1000 | U22: =P22*T22 -> 1000
F23: Rubber | G23: ='Kaladesh Refinery'!$K$13 -> 28.74549 | H23: Kaladesh Refinery | I23: Several Modules | O23: Particle Accelerator | P23: 2 | Q23: Final Stage | R23: Dark Matter Crystal | S23: Producing 35 with time Crystals | T23: =(245.2+735.6)/2 -> 490.4 | U23: =P23*T23 -> 980.8
F24: Limestone | G24: =86+2/5 -> 86.4 | H24: Miners | I24: Heavy Modular Frame Module | O24: Particle Accelerator | P24: 2 | Q24: Final Stage | R24: Dark Matter Crystal | S24: Producing 31.533 with time Crystals | T24: =(213.6+640.9)/2 -> 427.25 | U24: =P24*T24 -> 854.5
F25: Water | G25: =204+1084/5265 -> 204.20589 | H25: Water Extractors | I25: Heavy Modular Frame Module | O25: Particle Accelerator | P25: 1 | Q25: Final Stage | R25: Dark Matter Crystal | S25: Producing 13.733 without time Crystals | T25: =(304.2+912.6)/2 -> 608.4 | U25: =P25*T25 -> 608.4
F26: Nitrogen | G26: 146.4 | H26: Aetherflux Reactor | I26: Thermal Propulsion Rocket Module
F27: Copper Ore | G27: =71+19/75 -> 71.253333 | H27: Miners | I27: Heat Sinks & Casings Module
F28: Water | G28: =47+113/225 -> 47.502222 | H28: Water Extractors | I28: Heat Sinks & Casings Module
F29: Aluminum Ingots | G29: =356+4/15 -> 356.26667 | H29: Aetherflux Reactor | I29: Heat Sinks & Casings Module
F30: Caterium Ore | G30: =113+3/15 -> 113.2 | H30: Miners | I30: Radio Control Units Module
F31: Copper Ore | G31: =99+1/25 -> 99.04 | H31: Miners | I31: Radio Control Units Module
F32: Water | G32: =179+47/75 -> 179.62667 | H32: Water Extractors | I32: Radio Control Units Module
F33: Silica | G33: =52+4/5 -> 52.8 | H33: Tollarian Meltdown | I33: Radio Control Units Module
F34: Aluminum Casing | G34: 40 | H34: Riveteers District | I34: Radio Control Units Module
F35: Quartz Crystals | G35: 142 | H35: Aetherflux Reactor | I35: Radio Control Units Module
F36: Iron Ore | G36: =322+17/162 -> 322.10494 | H36: Miners | I36: Magnetic Field Generator & ECR Module
F37: Limestone | G37: =306+1/4 -> 306.25 | H37: Miners | I37: Magnetic Field Generator & ECR Module
F38: Water | G38: =255+5/24 -> 255.20833 | H38: Water Extractors | I38: Magnetic Field Generator & ECR Module
F39: Steel Ingots | G39: =309+1/6 -> 309.16667 | H39: Aetherflux Reactor | I39: Magnetic Field Generator & ECR Module | O39: Totals | P39: =SUM(U14:U38) -> 18779.75
F40: Caterium Ore | G40: =99 -> 99 | H40: Miners | I40: Magnetic Field Generator & ECR Module
F41: Plastic | G41: 38.5 | H41: Keldon Armory | I41: Magnetic Field Generator & ECR Module
F42: Aluminum Ingots | G42: 160 | H42: Aetherflux Reactor | I42: Ficsite Trigons
...
